pixdim[1,2,3] should be non-zero; setting 0 dims to 1
Traceback (most recent call last):
  File "/home/e.ty/.conda/envs/neuro/lib/python3.10/site-packages/nibabel/loadsave.py", line 90, in load
    stat_result = os.stat(filename)
FileNotFoundError: [Errno 2] No such file or directory: '/ceph/hcpdb/archive/HCP_1200/arc001/130114_3T/RESOURCES/MSMAllDeDrift/MNINonLinear/Results/rfMRI_REST1_RL/rfMRI_REST1_RL_Atlas_MSMAll_hp2000_clean.dtseries.nii'

During handling of the above exception, another exception occurred:

Traceback (most recent call last):
  File "/scratch/tyoeasley/brain_representations/gradient_reps/src/comp_HCP_gradients/compute_subj_gradients.py", line 302, in <module>
    par_HCP_diffusion_maps(subjID, args)
  File "/scratch/tyoeasley/brain_representations/gradient_reps/src/comp_HCP_gradients/compute_subj_gradients.py", line 37, in par_HCP_diffusion_maps
    data_list, outpath, cifti_headers = pull_subj_data(subjID,
  File "/scratch/tyoeasley/brain_representations/gradient_reps/src/comp_HCP_gradients/compute_subj_gradients.py", line 80, in pull_subj_data
    cifti_data = nib.load(fmri_fpath.replace('REST1_LR', session_id))
  File "/home/e.ty/.conda/envs/neuro/lib/python3.10/site-packages/nibabel/loadsave.py", line 92, in load
    raise FileNotFoundError(f"No such file or no access: '{filename}'")
FileNotFoundError: No such file or no access: '/ceph/hcpdb/archive/HCP_1200/arc001/130114_3T/RESOURCES/MSMAllDeDrift/MNINonLinear/Results/rfMRI_REST1_RL/rfMRI_REST1_RL_Atlas_MSMAll_hp2000_clean.dtseries.nii'
