multiprocessing.pool.RemoteTraceback: 
"""
Traceback (most recent call last):
  File "/home/e.ty/.conda/envs/alg_top_neuro/lib/python3.7/multiprocessing/pool.py", line 121, in worker
    result = (True, func(*args, **kwds))
  File "/home/e.ty/.conda/envs/alg_top_neuro/lib/python3.7/multiprocessing/pool.py", line 44, in mapstar
    return list(map(*args))
  File "/scratch/tyoeasley/brain_representations/src_py/run_lindecomp_stbl.py", line 21, in par_stbl_iters
    read_mode=False, reps=brainreps_data,write_mode=False)
  File "/mnt/beegfs/scratch/tyoeasley/brain_representations/src_py/lindecomp_stability.py", line 77, in run_stability_iters
    read_mode=False,dataset=reps,write_mode=write_mode)
  File "/mnt/beegfs/scratch/tyoeasley/brain_representations/src_py/lindecomp_brainrep.py", line 58, in pairwise_lin_decomp
    res_vars[i][j] = results
IndexError: list assignment index out of range
"""

The above exception was the direct cause of the following exception:

Traceback (most recent call last):
  File "/scratch/tyoeasley/brain_representations/src_py/run_lindecomp_stbl.py", line 43, in <module>
    decomp_vals,stbl_arch_dir = run_parallel_iters(output_basedir,n_workers)
  File "/scratch/tyoeasley/brain_representations/src_py/run_lindecomp_stbl.py", line 30, in run_parallel_iters
    P.map(par_stbl_iters,dirlocs)
  File "/home/e.ty/.conda/envs/alg_top_neuro/lib/python3.7/multiprocessing/pool.py", line 268, in map
    return self._map_async(func, iterable, mapstar, chunksize).get()
  File "/home/e.ty/.conda/envs/alg_top_neuro/lib/python3.7/multiprocessing/pool.py", line 657, in get
    raise self._value
IndexError: list assignment index out of range
