Traceback (most recent call last):
  File "/home/e.ty/.conda/envs/alg_top_neuro/lib/python3.7/site-packages/nibabel/loadsave.py", line 42, in load
    stat_result = os.stat(filename)
FileNotFoundError: [Errno 2] No such file or directory: 'sub-100206.dscalar.nii'

During handling of the above exception, another exception occurred:

Traceback (most recent call last):
  File "/scratch/tyoeasley/brain_representations/src_py/run_comp_Psim.py", line 4, in <module>
    cpm.comp_dist_mtx(sys.argv[1],sys.argv[2])
  File "/mnt/beegfs/scratch/tyoeasley/brain_representations/src_py/comp_Psim_mtx.py", line 14, in comp_dist_mtx
    Psim_mtx = comp_Psim_vals(subj_list)
  File "/mnt/beegfs/scratch/tyoeasley/brain_representations/src_py/comp_Psim_mtx.py", line 45, in comp_Psim_vals
    data_list[i] = parse.parse_fname(subj_list[i])
  File "/mnt/beegfs/scratch/tyoeasley/brain_representations/src_py/parse_neurodata.py", line 12, in parse_fname
    data=parser(fname)
  File "/mnt/beegfs/scratch/tyoeasley/brain_representations/src_py/parse_neurodata.py", line 24, in load_cifti_profumo_map
    map_mat = nib.load(fname)
  File "/home/e.ty/.conda/envs/alg_top_neuro/lib/python3.7/site-packages/nibabel/loadsave.py", line 44, in load
    raise FileNotFoundError(f"No such file or no access: '{filename}'")
FileNotFoundError: No such file or no access: 'sub-100206.dscalar.nii'
